WARNING 2024-01-25 12:48:25,749 django.request Bad Request: /api/instance/
WARNING 2024-01-25 12:48:36,026 django.request Bad Request: /api/instance/
WARNING 2024-01-25 12:48:43,296 django.request Bad Request: /api/instance/
WARNING 2024-01-25 12:54:56,125 django.request Bad Request: /api/instance/836cf9dc-bcb1-46ff-b47f-ee8723d6e8bf/redisgraph/check-module-loaded/
ERROR 2024-01-25 12:54:58,937 redisinsight Unknown command error from redis instance:
Traceback (most recent call last):
  File "./redisinsight/utils/__init__.py", line 199, in _wrapped_view
  File "./redisinsight/core/views/decorators.py", line 21, in wrapped_view
  File "./redisinsight/redisai/views.py", line 40, in _wrapped_view
  File "./redisinsight/redisai/views.py", line 85, in models_view
  File "./redisinsight/redisai/services.py", line 181, in list_models
  File "./redisinsight/redisai/services.py", line 157, in _list_models
  File "/usr/local/lib/python3.11/site-packages/redis/client.py", line 901, in execute_command
    return self.parse_response(conn, command_name, **options)
           ^^^^^^^^^^^^^^^^^^^^^^^^^^^^^^^^^^^^^^^^^^^^^^^^^^
  File "/usr/local/lib/python3.11/site-packages/redis/client.py", line 915, in parse_response
    response = connection.read_response()
               ^^^^^^^^^^^^^^^^^^^^^^^^^^
  File "/usr/local/lib/python3.11/site-packages/redis/connection.py", line 756, in read_response
    raise response
redis.exceptions.ResponseError: unknown command `AI._MODELSCAN`, with args beginning with: 
ERROR 2024-01-25 12:54:58,940 redisinsight Unknown command error from redis instance:
Traceback (most recent call last):
  File "./redisinsight/utils/__init__.py", line 199, in _wrapped_view
  File "./redisinsight/core/views/decorators.py", line 21, in wrapped_view
  File "./redisinsight/redisai/views.py", line 40, in _wrapped_view
  File "./redisinsight/redisai/views.py", line 224, in scripts_view
  File "./redisinsight/redisai/services.py", line 206, in list_scripts
  File "./redisinsight/redisai/services.py", line 185, in _list_scripts
  File "/usr/local/lib/python3.11/site-packages/redis/client.py", line 901, in execute_command
    return self.parse_response(conn, command_name, **options)
           ^^^^^^^^^^^^^^^^^^^^^^^^^^^^^^^^^^^^^^^^^^^^^^^^^^
  File "/usr/local/lib/python3.11/site-packages/redis/client.py", line 915, in parse_response
    response = connection.read_response()
               ^^^^^^^^^^^^^^^^^^^^^^^^^^
  File "/usr/local/lib/python3.11/site-packages/redis/connection.py", line 756, in read_response
    raise response
redis.exceptions.ResponseError: unknown command `AI._SCRIPTSCAN`, with args beginning with: 
ERROR 2024-01-25 12:54:58,947 django.request Unknown Status Code: /api/instance/836cf9dc-bcb1-46ff-b47f-ee8723d6e8bf/redisai/models/
ERROR 2024-01-25 12:54:58,959 django.request Unknown Status Code: /api/instance/836cf9dc-bcb1-46ff-b47f-ee8723d6e8bf/redisai/scripts/
WARNING 2024-01-25 12:54:59,573 django.request Bad Request: /api/instance/836cf9dc-bcb1-46ff-b47f-ee8723d6e8bf/redistimeseries/module-info/
WARNING 2024-01-25 12:55:00,503 django.request Bad Request: /api/instance/836cf9dc-bcb1-46ff-b47f-ee8723d6e8bf/check-redisearch-module-loaded/
